<sdf version='1.10'>
  <world name='empty'>
    <physics name='1ms' type='ignored'>
      <max_step_size>0.001</max_step_size>
      <real_time_factor>1</real_time_factor>
      <real_time_update_rate>1000</real_time_update_rate>
    </physics>
    <plugin name='gz::sim::systems::Physics' filename='gz-sim-physics-system' />
    <plugin name='gz::sim::systems::UserCommands' filename='gz-sim-user-commands-system' />
    <plugin name='gz::sim::systems::SceneBroadcaster' filename='gz-sim-scene-broadcaster-system' />
    <plugin name='gz::sim::systems::Contact' filename='gz-sim-contact-system' />
    <gravity>0 0 -9.8000000000000007</gravity>
    <magnetic_field>5.5644999999999998e-06 2.2875799999999999e-05 -4.2388400000000002e-05</magnetic_field>
    <atmosphere type='adiabatic' />
    <scene>
      <ambient>0.400000006 0.400000006 0.400000006 1</ambient>
      <background>0.699999988 0.699999988 0.699999988 1</background>
      <shadows>true</shadows>
    </scene>
    <model name='ground_plane'>
      <static>true</static>
      <link name='link'>
        <collision name='collision'>
          <geometry>
            <plane>
              <normal>0 0 1</normal>
              <size>10 10</size>
            </plane>
          </geometry>
          <surface>
            <friction>
              <ode />
            </friction>
            <bounce />
            <contact />
          </surface>
        </collision>
        <visual name='visual'>
          <geometry>
            <plane>
              <normal>0 0 1</normal>
              <size>10 10</size>
            </plane>
          </geometry>
          <material>
            <ambient>0.800000012 0.800000012 0.800000012 1</ambient>
            <diffuse>0.800000012 0.800000012 0.800000012 1</diffuse>
            <specular>0.800000012 0.800000012 0.800000012 1</specular>
          </material>
        </visual>
        <pose>0 0 0 0 0 0</pose>
        <inertial>
          <pose>0 0 0 0 0 0</pose>
          <mass>1</mass>
          <inertia>
            <ixx>1</ixx>
            <ixy>0</ixy>
            <ixz>0</ixz>
            <iyy>1</iyy>
            <iyz>0</iyz>
            <izz>1</izz>
          </inertia>
        </inertial>
        <enable_wind>false</enable_wind>
      </link>
      <pose>0 0 0 0 0 0</pose>
      <self_collide>false</self_collide>
    </model>
    <model name='wall_y1_red'>
      <static>true</static>
      <link name='link'>
        <collision name='collision'>
          <geometry>
            <plane>
              <normal>1 0 0</normal>
              <size>1 10</size>
            </plane>
          </geometry>
          <surface>
            <friction>
              <ode />
            </friction>
            <bounce />
            <contact />
          </surface>
        </collision>
        <visual name='visual'>
          <geometry>
            <plane>
              <normal>1 0 0</normal>
              <size>1 10</size>
            </plane>
          </geometry>
          <material>
            <ambient>0.800000012 0.000000012 0.000000012 1</ambient>
            <diffuse>0.800000012 0.000000012 0.00000012 1</diffuse>
            <specular>0.800000012 0.000000012 0.000000012 1</specular>
          </material>
        </visual>
        <pose>5 0 0.5 0 0 3.141592654</pose>
        <inertial>
          <pose>0 0 0 0 0 0</pose>
          <mass>1</mass>
          <inertia>
            <ixx>1</ixx>
            <ixy>0</ixy>
            <ixz>0</ixz>
            <iyy>1</iyy>
            <iyz>0</iyz>
            <izz>1</izz>
          </inertia>
        </inertial>
        <enable_wind>false</enable_wind>
      </link>
      <pose>0 0 0 0 0 0</pose>
      <self_collide>false</self_collide>
    </model>
    <model name='wall_y2_green'>
      <static>true</static>
      <link name='link'>
        <collision name='collision'>
          <geometry>
            <plane>
              <normal>1 0 0</normal>
              <size>1 10</size>
            </plane>
          </geometry>
          <surface>
            <friction>
              <ode />
            </friction>
            <bounce />
            <contact />
          </surface>
        </collision>
        <visual name='visual'>
          <geometry>
            <plane>
              <normal>1 0 0</normal>
              <size>1 10</size>
            </plane>
          </geometry>
          <material>
            <ambient>0.000000012 0.800000012 0.000000012 1</ambient>
            <diffuse>0.000000012 0.800000012 0.000000012 1</diffuse>
            <specular>0.000000012 0.800000012 0.000000012 1</specular>
          </material>
        </visual>
        <pose>-5 0 0.5 0 0 0</pose>
        <inertial>
          <pose>0 0 0 0 0 0</pose>
          <mass>1</mass>
          <inertia>
            <ixx>1</ixx>
            <ixy>0</ixy>
            <ixz>0</ixz>
            <iyy>1</iyy>
            <iyz>0</iyz>
            <izz>1</izz>
          </inertia>
        </inertial>
        <enable_wind>false</enable_wind>
      </link>
      <pose>0 0 0 0 0 0</pose>
      <self_collide>false</self_collide>
    </model>
    <model name='wall_x1_blue'>
      <static>true</static>
      <link name='link'>
        <collision name='collision'>
          <geometry>
            <plane>
              <normal>0 1 0</normal>
              <size>1 10</size>
            </plane>
          </geometry>
          <surface>
            <friction>
              <ode />
            </friction>
            <bounce />
            <contact />
          </surface>
        </collision>
        <visual name='visual'>
          <geometry>
            <plane>
              <normal>0 1 0</normal>
              <size>1 10</size>
            </plane>
          </geometry>
          <material>
            <ambient>0.000000012 0.000000012 0.800000012 1</ambient>
            <diffuse>0.000000012 0.000000012 0.800000012 1</diffuse>
            <specular>0.000000012 0.000000012 0.800000012 1</specular>
          </material>
        </visual>
        <pose>0 -5 0.5 0 1.570796 0</pose>
        <inertial>
          <pose>0 0 0 0 0 0</pose>
          <mass>1</mass>
          <inertia>
            <ixx>1</ixx>
            <ixy>0</ixy>
            <ixz>0</ixz>
            <iyy>1</iyy>
            <iyz>0</iyz>
            <izz>1</izz>
          </inertia>
        </inertial>
        <enable_wind>false</enable_wind>
      </link>
      <pose>0 0 0 0 0 0</pose>
      <self_collide>false</self_collide>
    </model>    
    <model name='wall_x2_yellow'>
      <static>true</static>
      <link name='link'>
        <collision name='collision'>
          <geometry>
            <plane>
              <normal>0 1 0</normal>
              <size>1 10</size>
            </plane>
          </geometry>
          <surface>
            <friction>
              <ode />
            </friction>
            <bounce />
            <contact />
          </surface>
        </collision>
        <visual name='visual'>
          <geometry>
            <plane>
              <normal>0 1 0</normal>
              <size>1 10</size>
            </plane>
          </geometry>
          <material>
            <ambient>0.800000012 0.800000012 0.000000012 1</ambient>
            <diffuse>0.800000012 0.800000012 0.000000012 1</diffuse>
            <specular>0.800000012 0.800000012 0.000000012 1</specular>
          </material>
        </visual>
        <pose>0 5 0.5 0 1.570796 3.14159265</pose>
        <inertial>
          <pose>0 0 0 0 0 0</pose>
          <mass>1</mass>
          <inertia>
            <ixx>1</ixx>
            <ixy>0</ixy>
            <ixz>0</ixz>
            <iyy>1</iyy>
            <iyz>0</iyz>
            <izz>1</izz>
          </inertia>
        </inertial>
        <enable_wind>false</enable_wind>
      </link>
      <pose>0 0 0 0 0 0</pose>
      <self_collide>false</self_collide>
    </model>        
    <model name="cart_rigid_suspension">
      <plugin filename="libgz-sim-diff-drive-system.so" name="gz::sim::systems::DiffDrive">
        <left_joint>wheel_front_left_spin</left_joint>
        <right_joint>wheel_front_right_spin</right_joint>
        <wheel_separation>0.596</wheel_separation>
        <wheel_radius>0.15</wheel_radius>
        <odom_publish_frequency>1</odom_publish_frequency>
        <topic>cmd_vel</topic>
        <max_linear_velocity>100</max_linear_velocity>
        <max_linear_acceleration>100</max_linear_acceleration>

      </plugin>
      <plugin filename="libgz-sim-pose-publisher-system.so" name="gz::sim::systems::PosePublisher">
        <publish_link_pose>False</publish_link_pose>
        <publish_visual_pose>False</publish_visual_pose>
        <publish_collision_pose>False</publish_collision_pose>
        <publish_sensor_pose>False</publish_sensor_pose>
        <publish_model_pose>True</publish_model_pose>
        <publish_nested_model_pose>True</publish_nested_model_pose>
        <use_pose_vector_msg>False</use_pose_vector_msg>
        <update_frequency>100</update_frequency>
      </plugin>

      <pose>0 0 0 0 0.17453 0</pose>
      <link name="chassis">
        <pose>0 0 0.65 0 0 0</pose>
        <inertial>
          <pose>0 0 1 0 0 0</pose>
          <mass>1</mass>
          <inertia>
            <!--
                  <ixx>0.8416666666666667</ixx>
                  <iyy>0.21666666666666667</iyy>
                  <izz>1.0416666666666667</izz>
                  -->
            <ixx>0.020833</ixx>
            <iyy>0.75</iyy>
            <izz>0.770833</izz>
            <ixy>0</ixy>
            <ixz>0</ixz>
            <iyz>0</iyz>
          </inertia>
        </inertial>
        <collision name="collision">
          <geometry>
            <box>
              <size>0.1 0.5 1.0</size>
            </box>
          </geometry>
        </collision>
        <visual name="visual">
          <geometry>
            <box>
              <size>0.1 0.5 1.0</size>
            </box>
          </geometry>
          <material>
            <ambient>0.3 0.3 0.3 1.0</ambient>
            <diffuse>0.7 0.7 0.7 1.0</diffuse>
            <specular>0.1 0.1 0.1 1.0</specular>
          </material>
        </visual>
      </link>
      <link name="wheel_front_left">
        <pose>0 0.298 0.15 -1.5707963267948966 0 0</pose>
        <inertial>
          <mass>0.5</mass>
          <inertia>
            <ixx>0.0030791666666666667</ixx>
            <iyy>0.0030791666666666667</iyy>
            <izz>0.005625</izz>
            <ixy>0</ixy>
            <ixz>0</ixz>
            <iyz>0</iyz>
          </inertia>
        </inertial>
        <collision name="collision">
          <geometry>
            <cylinder>
              <radius>0.15</radius>
              <length>0.08</length>
            </cylinder>
          </geometry>
        </collision>
        <visual name="visual">
          <geometry>
            <cylinder>
              <radius>0.15</radius>
              <length>0.08</length>
            </cylinder>
          </geometry>
          <material>
            <ambient>0 0 0 1.0</ambient>
            <diffuse>0 0 0 1.0</diffuse>
            <specular>0.01 0.01 0.01 1.0</specular>
          </material>
        </visual>
      </link>
      <joint name="wheel_front_left_spin" type="revolute">
        <parent>chassis</parent>
        <child>wheel_front_left</child>
        <axis>
          <xyz>0 0 1</xyz>
        </axis>
      </joint>
      <link name="wheel_front_right">
        <pose>0 -0.298 0.15 -1.5707963267948966 0 0</pose>
        <inertial>
          <mass>0.5</mass>
          <inertia>
            <ixx>0.0030791666666666667</ixx>
            <iyy>0.0030791666666666667</iyy>
            <izz>0.005625</izz>
            <ixy>0</ixy>
            <ixz>0</ixz>
            <iyz>0</iyz>
          </inertia>
        </inertial>
        <collision name="collision">
          <geometry>
            <cylinder>
              <radius>0.15</radius>
              <length>0.08</length>
            </cylinder>
          </geometry>
        </collision>
        <visual name="visual">
          <geometry>
            <cylinder>
              <radius>0.15</radius>
              <length>0.08</length>
            </cylinder>
          </geometry>
          <material>
            <ambient>0 0 0 1.0</ambient>
            <diffuse>0 0 0 1.0</diffuse>
            <specular>0.01 0.01 0.01 1.0</specular>
          </material>
        </visual>
      </link>
      <joint name="wheel_front_right_spin" type="revolute">
        <parent>chassis</parent>
        <child>wheel_front_right</child>
        <axis>
          <xyz>0 0 1</xyz>
        </axis>
      </joint>
    </model>
    <light name='sun' type='directional'>
      <pose>0 0 10 0 0 0</pose>
      <cast_shadows>true</cast_shadows>
      <intensity>1</intensity>
      <direction>-0.5 0.10000000000000001 -0.90000000000000002</direction>
      <diffuse>0.800000012 0.800000012 0.800000012 1</diffuse>
      <specular>0.200000003 0.200000003 0.200000003 1</specular>
      <attenuation>
        <range>1000</range>
        <linear>0.01</linear>
        <constant>0.90000000000000002</constant>
        <quadratic>0.001</quadratic>
      </attenuation>
      <spot>
        <inner_angle>0</inner_angle>
        <outer_angle>0</outer_angle>
        <falloff>0</falloff>
      </spot>
    </light>
  </world>
</sdf>